Workbook

Sheet Scaling Laws
B1: Task/Setting | C1: Loss Function | D1: Architecture | E1: Paper | F1: Gain from 10x Scaling -- Observed | I1: Compute Optimal | K1: Observed
F2: L(C) | G2: L(N) | H2: L(D) | I2: Nopt | J2: Dopt | K2: L(C) | L2: L(N) | M2: L(D) | N2: Source | O2: alpha N | P2: alpha D | Q2: Nc | R2: Dc | S2: Loss Function | T2: Other Hyperparameters | U2: Min Model Size | V2: Max Model Size | W2: SC Loss Drop per 10x FLOPs | X2: SC FLOP range | Y2: SC Loss range | Z2: SC Power Law Exponent | AA2: SC Application | AB2: Paper scaling-law form (as stated)
A3: Language | B3: Language modeling | C3: Cross-entropy / NLL | D3: Transformer | E3: LLM -- Kaplan (2020) | F3: =IF(K3="", "",(1-10^K3)) -> 0.10463523 | G3: =IF(L3="", "",(1-10^L3)) -> 0.16054001 | H3: =IF(M3="", "",(1-10^M3)) -> 0.19647388 | I3: 0.73 | J3: 0.27 | K3: -0.048 | L3: -0.076 | M3: -0.095 | N3: https://arxiv.org/abs/2001.08361 | W3: 10% | X3: 10^13–10^18 | Y3: 3.0–6.0 (test) | Z3: -0.05 | AA3: Text prediction | AB3: Kaplan et al. (2020): test cross-entropy fit with an irreducible term, e.g. L(N,D)=L∞+(Nc/N)^αN+(Dc/D)^αD; compute-only fits use a similar power law in C with +L∞.
A4: Language | B4: Language modeling | C4: Cross-entropy / NLL | D4: Transformer | E4: LLM -- Chinchilla | F4: =IF(K4="", "",(1-10^K4)) | G4: =IF(L4="", "",(1-10^L4)) -> 0.54185811 | H4: =IF(M4="", "",(1-10^M4)) -> 0.48119996 | I4: 0.5 | J4: 0.5 | L4: -0.339 | M4: -0.285 | N4: https://arxiv.org/pdf/2203.15556 | W4: 8%–14% | X4: 10^17–10^22 | Y4: 2.0–4.0 (training) | AA4: Text prediction | AB4: Hoffmann et al. (2022, Chinchilla): compute-optimal scaling N_opt∝C^0.49 and D_opt∝C^0.51; paper discusses a curved FLOP–loss frontier rather than a single fixed compute exponent across all scales.
A5: Language | B5: Language modeling | C5: Cross-entropy / NLL | D5: Transformer | E5: DeepSeek | F5: =IF(K5="", "",(1-10^K5)) -> 0.21113988 | G5: =IF(L5="", "",(1-10^L5)) | H5: =IF(M5="", "",(1-10^M5)) | I5: 0.52 | J5: 0.48 | K5: -0.103 | N5: https://arxiv.org/pdf/2401.02954
A6: Language | B6: Language modeling | C6: Cross-entropy / NLL | D6: Transformer | E6: Data-Constrained Scaling (Muennighoff et al., 2023) | F6: =IF(K6="", "",(1-10^K6)) | G6: =IF(L6="", "",(1-10^L6)) -> 0.55639136 | H6: =IF(M6="", "",(1-10^M6)) -> 0.55639136 | L6: -0.353 | M6: -0.353 | N6: https://arxiv.org/abs/2305.16264
A7: Language | B7: Language modeling | C7: Cross-entropy / NLL | D7: Transformer | E7: Mixed-Modal Scaling (Aghajanyan et al., 2023) — Text (Causal) | F7: =IF(K7="", "",(1-10^K7)) | G7: =IF(L7="", "",(1-10^L7)) -> 0.32391702 | H7: =IF(M7="", "",(1-10^M7)) -> 0.41115634 | L7: -0.17 | M7: -0.23 | N7: https://arxiv.org/abs/2301.03728
A8: Language | B8: Language modeling (pretrain/transfer) | C8: Cross-entropy / NLL | D8: Transformer | E8: Transfer scaling (Hernandez et al. 2021) | F8: =IF(K8="", "",(1-10^K8)) | G8: =IF(L8="", "",(1-10^L8)) -> 0.58313062 | H8: =IF(M8="", "",(1-10^M8)) -> 0.33930655 | L8: -0.38 | M8: -0.18 | N8: OpenAI 2102.01293 | S8: Test loss (cross-entropy) | W8: 17%–23% | X8: 10^13–10^20 | Y8: 1–3 (test) | AA8: Transfer learning | AB8: Hernandez et al. (2021): models transfer as an “effective data” term (D_T) so downstream performance behaves like training on D + D_T tokens; provides transfer scaling relationships rather than a single universal FLOP exponent.
A9: Language | B9: Language modeling | C9: Cross-entropy / NLL | D9: Transformer | E9: Trainable params determine loss–compute scaling (Chatelain et al. 2022) | F9: =IF(K9="", "",(1-10^K9)) -> 0.090086727 | G9: =IF(L9="", "",(1-10^L9)) | H9: =IF(M9="", "",(1-10^M9)) | K9: -0.041 | N9: LightOn / PMLR v163 Chatelain22a | S9: Test loss (cross-entropy) | W9: 5%–11% | X9: 10^16–10^19 | Y9: 5–8 (test) | Z9: -0.041 | AA9: French text prediction | AB9: Chatelain et al. (2022): Figure 1 fits test loss ≈ 3.22 · C^{-0.041}. Compute C estimated as C=6·N·B·S (PF-days), with N=trainable non-embedding params.
A10: Language | B10: Language modeling | C10: Cross-entropy / NLL | D10: Transformer | E10: NLP benchmark scaling (Tay et al. 2022) | F10: =IF(K10="", "",(1-10^K10)) | G10: =IF(L10="", "",(1-10^L10)) | H10: =IF(M10="", "",(1-10^M10)) | N10: Google 2210.11399 | S10: Test error (benchmark score) | W10: 22%–35% | X10: 10^23–10^25 | Y10: 31%–58% (test error) | AA10: NLP benchmarks | AB10: Tay et al. (2022): compares methods that “transcend” baseline scaling with ~0.1% extra compute; shows scaling curves on NLP benchmarks but does not present a single canonical power-law exponent in the paper text (SC table summarizes % drop/decade over the shown range).
A11: Language | B11: Language modeling (pretrain/transfer) | C11: Cross-entropy / NLL | D11: Transformer | E11: Ivgi 2022 | F11: =IF(K11="", "",(1-10^K11)) | G11: =IF(L11="", "",(1-10^L11)) -> 0.29205422 | H11: =IF(M11="", "",(1-10^M11)) | L11: -0.15 | N11: https://arxiv.org/abs/2202.06387
A12: Language | B12: Machine translation | C12: Cross-entropy / NLL | D12: Transformer | E12: Fernandes et al. 2023 | F12: =IF(K12="", "",(1-10^K12)) | G12: =IF(L12="", "",(1-10^L12)) -> 0.48713862 | H12: =IF(M12="", "",(1-10^M12)) | L12: -0.29 | N12: https://arxiv.org/abs/2302.09650
A13: Language | B13: Machine translation | C13: Cross-entropy / NLL | D13: Transformer | E13: (Gordon et al. 2021) — Ru-En | F13: =IF(K13="", "",(1-10^K13)) | G13: =IF(L13="", "",(1-10^L13)) -> 0.22375288 | H13: =IF(M13="", "",(1-10^M13)) -> 0.58313062 | L13: -0.11 | M13: -0.38 | N13: https://aclanthology.org/2021.emnlp-main.478/ | Q13: 21.62 | R13: 13.81 | S13: Test cross-entropy loss | T13: Nc and Dc are reported as log N_C and log D_C in the paper’s Table 1. | AB13: Gordon et al. (2021): loss L(N,D)= [ (N_C/N)^(α_N/α_D) + (D_C/D) ]^{α_D} (their Eq. 1; Table 1 reports α_N, α_D, log N_C, log D_C for each language pair).
A14: Language | B14: Machine translation | C14: Cross-entropy / NLL | D14: Transformer | E14: (Bansal et al. 2022 | F14: =IF(K14="", "",(1-10^K14)) | G14: =IF(L14="", "",(1-10^L14)) | H14: =IF(M14="", "",(1-10^M14)) -> 0.4629682 | M14: -0.27 | N14: https://arxiv.org/abs/2202.01994
A15: Language | B15: Machine translation | C15: Cross-entropy / NLL | D15: Transformer | E15: NMT data-scaling exponent p (Bansal et al. 2022) — Figure 10 Zh→En architecture | F15: =IF(K15="", "",(1-10^K15)) | G15: =IF(L15="", "",(1-10^L15)) | H15: =IF(M15="", "",(1-10^M15)) -> 0.43765867 | M15: -0.25 | N15: https://arxiv.org/abs/2202.01994 | S15: Test log-perplexity (log-PPL) | T15: Figure 10 label: 'The Role of Architecture in Zh En Models, p = 0.25'. | AB15: Figure 10: scaling exponent p for Zh→En architecture comparison (common p, different α,C).
A16: Language | D16: Transformer | E16: Beyond Language Modeling: An Exploration of Multimodal Pretraining | I16: 0.47 | J16: 0.53 | N16: https://arxiv.org/abs/2603.03276
A17: Code | B17: Code language modeling / generation | C17: Cross-entropy / NLL | D17: Transformer | E17: Program Synthesis with Large Language Models | F17: =IF(K17="", "",(1-10^K17)) | G17: =IF(L17="", "",(1-10^L17)) | H17: =IF(M17="", "",(1-10^M17)) | N17: https://arxiv.org/abs/2108.07732
A18: Code | B18: Code language modeling / generation | C18: Cross-entropy / NLL | D18: Transformer | E18: Codex (GPT-3 era) | F18: =IF(K18="", "",(1-10^K18)) | G18: =IF(L18="", "",(1-10^L18)) -> 0.25868976 | H18: =IF(M18="", "",(1-10^M18)) | L18: -0.13 | N18: https://arxiv.org/pdf/2107.03374
A19: Code | B19: Code language modeling / generation | C19: Cross-entropy / NLL | D19: Transformer | E19: Scaling Laws for Code: A More Data-Hungry Regime | F19: =IF(K19="", "",(1-10^K19)) -> 0.33930655 | G19: =IF(L19="", "",(1-10^L19)) -> 0.66886888 | H19: =IF(M19="", "",(1-10^M19)) -> 0.48713862 | K19: -0.18 | L19: -0.48 | M19: -0.29 | N19: https://arxiv.org/abs/2510.08702
A20: Math | B20: Mathematical reasoning | C20: Cross-entropy / NLL | D20: Transformer | E20: Extrapolate | F20: =IF(K20="", "",(1-10^K20)) -> 0.30816903 | G20: =IF(L20="", "",(1-10^L20)) -> 0.32391702 | H20: =IF(M20="", "",(1-10^M20)) | I20: 0.69 | K20: -0.16 | L20: -0.17 | N20: ​​https://arxiv.org/pdf/2010.14701
A21: Multimodal | B21: Multimodal autoregressive pretraining | C21: Cross-entropy / NLL | D21: Transformer | E21: Scaling Laws for Native Multimodal Models | F21: =IF(K21="", "",(1-10^K21)) | G21: =IF(L21="", "",(1-10^L21)) -> 0.48713862 | H21: =IF(M21="", "",(1-10^M21)) -> 0.54291181 | L21: -0.29 | M21: -0.34 | N21: https://arxiv.org/pdf/2504.07951
A22: Image | E22: Beyond Language Modeling: An Exploration of Multimodal Pretraining | I22: 0.37 | J22: 0.63 | N22: https://arxiv.org/abs/2603.03276
A23: Image | B23: Image generation | C23: Cross-entropy / NLL | D23: Transformer | E23: 8x8 | F23: =IF(K23="", "",(1-10^K23)) -> 0.42456006 | G23: =IF(L23="", "",(1-10^L23)) -> 0.35434577 | H23: =IF(M23="", "",(1-10^M23)) | I23: 0.64 | K23: -0.24 | L23: -0.19 | N23: ​​https://arxiv.org/pdf/2010.14701
A24: Image | B24: Image generation | C24: Cross-entropy / NLL | D24: Transformer | E24: 16x16 | F24: =IF(K24="", "",(1-10^K24)) -> 0.39744041 | G24: =IF(L24="", "",(1-10^L24)) -> 0.30816903 | H24: =IF(M24="", "",(1-10^M24)) | I24: 0.75 | K24: -0.22 | L24: -0.16 | N24: ​​https://arxiv.org/pdf/2010.14701
A25: Image | B25: Image generation | C25: Cross-entropy / NLL | D25: Transformer | E25: 32x32 | F25: =IF(K25="", "",(1-10^K25)) -> 0.25868976 | G25: =IF(L25="", "",(1-10^L25)) -> 0.20567177 | H25: =IF(M25="", "",(1-10^M25)) | I25: 0.65 | K25: -0.13 | L25: -0.1 | N25: ​​https://arxiv.org/pdf/2010.14701
A26: Image | B26: Text-to-image generation | C26: Cross-entropy / NLL | D26: Transformer | E26: Text-to-Im | F26: =IF(K26="", "",(1-10^K26)) -> 0.30816903 | G26: =IF(L26="", "",(1-10^L26)) -> 0.29205422 | H26: =IF(M26="", "",(1-10^M26)) | I26: 0.7 | K26: -0.16 | L26: -0.15 | N26: ​​https://arxiv.org/pdf/2010.14701 | W26: 6%–11% | X26: 10^14–10^20 | Y26: 2–3 (test) | Z26: -0.16 | AA26: Text-to-image | AB26: Henighan et al. (2020): modality-specific loss fits follow a power law in compute (often with an irreducible loss term), i.e. L(C)=L∞+k·C^αC; here αC≈-0.16.
A27: Image | B27: Image captioning | C27: Cross-entropy / NLL | D27: Transformer | E27: Im-to-Text | F27: =IF(K27="", "",(1-10^K27)) -> 0.29205422 | G27: =IF(L27="", "",(1-10^L27)) -> 0.30816903 | H27: =IF(M27="", "",(1-10^M27)) | I27: 0.72 | K27: -0.15 | L27: -0.16 | N27: ​​https://arxiv.org/pdf/2010.14701 | W27: 6%–11% | X27: 10^14–10^20 | Y27: 2–3 (test) | Z27: -0.15 | AA27: Image-to-text | AB27: Henighan et al. (2020): modality-specific loss fits follow a power law in compute (often with an irreducible loss term), i.e. L(C)=L∞+k·C^αC; here αC≈-0.15.
A28: Image | B28: Image-text contrastive pretraining | C28: Contrastive (InfoNCE) | D28: Dual-encoder | E28: ZeroShot ImageNet | F28: =IF(K28="", "",(1-10^K28)) -> 0.26717547 | G28: =IF(L28="", "",(1-10^L28)) | H28: =IF(M28="", "",(1-10^M28)) | K28: -0.135 | N28: https//arxiv.org/abs/2212.07143
A29: Image | B29: Image generation | C29: Cross-entropy / NLL | D29: Transformer | E29: Autoregressive Visual Modeling | F29: =IF(K29="", "",(1-10^K29)) -> 0.25868976 | G29: =IF(L29="", "",(1-10^L29)) -> 0.41115634 | H29: =IF(M29="", "",(1-10^M29)) | K29: -0.13 | L29: -0.23 | N29: https://arxiv.org/pdf/2404.02905
A30: Image | B30: Text-to-image generation | C30: Diffusion denoising loss | D30: Diffusion | E30: Diffusion Transformers | F30: =IF(K30="", "",(1-10^K30)) | G30: =IF(L30="", "",(1-10^L30)) | H30: =IF(M30="", "",(1-10^M30)) | I30: 0.57 | J30: 0.43 | N30: https://arxiv.org/pdf/2410.08184 | X30: 10^16-10^18
A31: Image | B31: Large-scale supervised image classification pretraining (JFT ~4B) + transfer (linear probe/zero-shot/segmentation/depth/video) | C31: Sigmoid cross-entropy (multi-label classification) for pretraining; downstream: task-specific (e.g., softmax CE for ImageNet fine-tune) | D31: Vision Transformer (encoder-only) w/ parallel Attention+MLP blocks, QK LayerNorm (QK-normalization), omit bias on QKV + LayerNorm | E31: Scaling Vision Transformers to 22 Billion Parameters (Dehghani et al., 2023) — arXiv:2302.05442 | F31: =IF(K31="", "",(1-10^K31)) | G31: =IF(L31="", "",(1-10^L31)) -> 0.073170177 | H31: =IF(M31="", "",(1-10^M31)) | L31: -0.033 | N31: https://arxiv.org/abs/2302.05442
A32: Image | B32: Text-to-image generation | C32: Diffusion denoising loss | D32: Diffusion | E32: On the Scalability of Diffusion-based Text-to-Image Generation (Li, Zou, …) | F32: =IF(K32="", "",(1-10^K32)) -> 0.045007414 | G32: =IF(L32="", "",(1-10^L32)) -> 0.22375288 | H32: =IF(M32="", "",(1-10^M32)) -> 0.066745699 | K32: -0.02 | L32: -0.11 | M32: -0.03 | N32: https://openreview.net/pdf/a5aba397592a333dfb1a2450b8f755ad0f5de144.pdf
A33: Image | B33: Image generation | C33: Adversarial (GAN) | D33: GAN | E33: Scalable GANs with Transformers (Hyun, Lee, Heo) | F33: =IF(K33="", "",(1-10^K33)) -> 0.65005483 | G33: =IF(L33="", "",(1-10^L33)) | H33: =IF(M33="", "",(1-10^M33)) | K33: -0.456 | N33: https://arxiv.org/abs/2509.24935
A34: Video | B34: Video modeling | C34: Cross-entropy / NLL | D34: Transformer | E34: Video VQ 16x16 | F34: =IF(K34="", "",(1-10^K34)) | G34: =IF(L34="", "",(1-10^L34)) | H34: =IF(M34="", "",(1-10^M34)) | I34: 0.71 | N34: ​​https://arxiv.org/pdf/2010.14701
A35: Video | B35: Video generation | C35: Diffusion denoising loss | D35: Diffusion | E35: Diffusion Transformers | F35: =IF(K35="", "",(1-10^K35)) | G35: =IF(L35="", "",(1-10^L35)) | H35: =IF(M35="", "",(1-10^M35)) | I35: 0.41 | N35: https://arxiv.org/abs/2411.17470
A36: World Model | B36: World modeling | C36: Cross-entropy / NLL | D36: Transformer | E36: Wayve Gaia 1 | F36: =IF(K36="", "",(1-10^K36)) -> 0.28055102 | K36: -0.143 | N36: https://arxiv.org/pdf/2309.17080
A37: World Model | B37: World modeling | C37: Cross-entropy / NLL | D37: Transformer | E37: Wayve Gaia 3 | F37: =IF(K37="", "",(1-10^K37)) -> 0.11284399 | G37: =IF(L37="", "",(1-10^L37)) | H37: =IF(M37="", "",(1-10^M37)) | K37: -0.052 | N37: https://wayve.ai/thinking/gaia-3/
A38: World Model | B38: World modeling | C38: Cross-entropy / NLL | D38: Transformer | E38: Genie 1 | F38: =IF(K38="", "",(1-10^K38)) -> 0.17775735 | G38: =IF(L38="", "",(1-10^L38)) | H38: =IF(M38="", "",(1-10^M38)) | K38: -0.085 | N38: https://arxiv.org/pdf/2402.15391
A39: World Model | B39: World modeling | C39: Noise MSE | D39: Diffusion | E39: Sherry Yang | F39: =IF(K39="", "",(1-10^K39)) | G39: =IF(L39="", "",(1-10^L39)) -> 0.22375288 | H39: =IF(M39="", "",(1-10^M39)) | L39: -0.11 | N39: "Scaling World Model Pretraining" by Sherry Yang, Manuscript in Preparation but graph from presentation at World Models Conference
A40: World Model | B40: Behavior cloning (imitation learning) | C40: Cross-entropy / NLL | D40: Transformer | E40: Behavior Cloning -- Token 540 | F40: =IF(K40="", "",(1-10^K40)) -> 0.066745699 | G40: =IF(L40="", "",(1-10^L40)) | H40: =IF(M40="", "",(1-10^M40)) | I40: 0.32 | J40: 0.78 | K40: -0.03 | N40: https://arxiv.org/pdf/2411.04434
...

Sheet Tokens to Param
A1: Dense Models | G1: PLMs | U1: Genomics
A2: Model (year) | B2: Params | C2: Pretrain tokens | D2: Tokens / param | G2: Model | H2: Objective | I2: Parameters | J2: Training tokens | K2: Training compute (FLOPs) | L2: Tokens / parms | M2: Reported vs estimated | N2: Notes | U2: Model | V2: Tokenization | W2: Params (#) | X2: Train tokens (#) | Y2: bp equiv (#) | Z2: Reported training compute | AA2: Est train compute | AB2: Est train FLOPs (#) | AC2: Tokens / Param
A3: LLaMA 65B (2023) (ar5iv) | B3: 65B | C3: 1.4T | D3: 21.54 | G3: ESM-2 (3B) | H3: MLM | I3: 3000000000 | J3: 1000000000000 | K3: 1.68e+22 | L3: =J3/I3 -> 333.33333 | M3: Reported (NeurIPS 2024 Table 5) | N3: Tokens and FLOPs reported as 'Train. Tokens' and 'FLOPs'. | U3: NTv3_650M_pre (InstaDeep) | V3: DNA char-level | W3: 700000000 | X3: 9000000000000 | Y3: 9000000000000 | Z3: Not stated in model card | AA3: 37.80 ZFLOPs | AB3: 3.78e+22 | AC3: =X3/W3 -> 12857.143
A4: Llama 2 70B (2023) (Hugging Face) | B4: 70B | C4: 2.0T | D4: 28.57 | G4: ProGen2-xlarge | H4: CLM | I4: 6400000000 | J4: 350000000000 | K4: 1.34e+22 | L4: =J4/I4 -> 54.6875 | M4: Reported (NeurIPS 2024 Table 5) | N4: Tokens and FLOPs reported as 'Train. Tokens' and 'FLOPs'. | U4: Evo2-7B | V4: DNA single-base | W4: 6500000000 | X4: 2400000000000 | Y4: 2400000000000 | Z4: Not stated in table | AA4: 93.60 ZFLOPs | AB4: 9.36e+22 | AC4: =X4/W4 -> 369.23077
A5: Falcon 180B (2023) (arXiv) | B5: 180B | C5: >3.5T | D5: 19.44 | G5: ProGen2-large | H5: CLM | I5: 2700000000 | J5: 200000000000 | K5: 3.24e+21 | L5: =J5/I5 -> 74.074074 | M5: Estimated (6×params×tokens) | N5: Tokens computed from batch_size(500k)×steps(400k) in ProGen2 paper Table 1. | U5: GENERator-1B | V5: DNA 6-mer (non-overlap assumed) | W5: 1200000000 | X5: 370000000000 | Y5: 2220000000000 | Z5: 11,776 A100-hours (32 GPUs × 368 hours) | AA5: 2.66 ZFLOPs | AB5: 2.664e+21 | AC5: =X5/W5 -> 308.33333
A6: Qwen 72B (2023) (GitHub) | B6: 72B | C6: 3.0T | D6: 41.67 | G6: ProGen2-medium | H6: CLM | I6: 764000000 | J6: 175000000000 | K6: 8.022e+20 | L6: =J6/I6 -> 229.05759 | M6: Estimated (6×params×tokens) | N6: Tokens computed from batch_size(500k)×steps(350k) in ProGen2 paper Table 1. | U6: Nucleotide Transformer v2 (500M) | V6: 6-mer when possible (else single) | W6: 500000000 | X6: 900000000000 | Y6: 5400000000000 | Z6: Trained on 8×A100 80GB (duration not given) | AA6: 2.70 ZFLOPs | AB6: 2.7e+21 | AC6: =X6/W6 -> 1800
A7: Qwen2 72B (2024) (arXiv) | B7: 72B | C7: 7.0T | D7: 97.22 | G7: ProGen2-small | H7: CLM | I7: 151000000 | J7: 175000000000 | K7: 1.5855e+20 | L7: =J7/I7 -> 1158.9404 | M7: Estimated (6×params×tokens) | N7: Tokens computed from batch_size(500k)×steps(350k) in ProGen2 paper Table 1. | U7: Nucleotide Transformer (NT-2500M-multi) | V7: DNA 6-mer (non-overlap assumed) | W7: 2537000000 | X7: 300000000000 | Y7: 1800000000000 | Z7: Not reported in that table | AA7: 4.57 ZFLOPs | AB7: 4.567e+21 | AC7: =X7/W7 -> 118.2499
A8: Llama 3 70B (2024) (Hugging Face) | B8: 70B | C8: 15T | D8: 214.29 | G8: ProGen3 | I8: 12600000000 | J8: 1500000000000 | L8: =J8/I8 -> 119.04762 | U8: DNABERT-2 | V8: BPE | W8: 117000000 | X8: 262000000000 | Y8: N/A | Z8: Not reported in that table | AA8: 183.92 EFLOPs | AB8: 1.839e+20 | AC8: =X8/W8 -> 2239.3162
A9: Llama 3.1 405B (2024) (AI Meta) | B9: 405B | C9: 15T | D9: 37.04 | G9: ESM3 | H9: Multimodal generative | I9: 98000000000 | J9: 771000000000 | K9: 1.07e+24 | L9: =J9/I9 -> 7.8673469 | M9: Reported (EvolutionaryScale) | N9: Tokens are reported as 'unique tokens'. | U9: DNABERT (6-mer) | V9: 6-mer (overlap in original DNABERT) | W9: 89000000 | X9: 122000000000 | Y9: 122000000000 | Z9: ~25 days on 8×NVIDIA 2080Ti GPUs | AA9: 65.15 EFLOPs | AB9: 6.515e+19 | AC9: =X9/W9 -> 1370.7865
A10: Nemotron-4 340B (2024) (arXiv) | B10: 340B | C10: 9T | D10: 26.47 | G10: xTrimoPGLM | H10: Protein LM | I10: 100000000000 | J10: 1000000000000 | K10: 6e+23 | L10: =J10/I10 -> 10 | M10: Reported (~operations) (Epoch AI blog) | N10: Epoch reports ~6e23 operations and 1T tokens; also mentions 768 A100s and date range. | U10: HyenaDNA | V10: DNA single-base | W10: 55000000 | X10: 3000000000 | Y10: 3000000000 | Z10: Not stated in table | AA10: 0.99 EFLOPs | AB10: 9.9e+17 | AC10: =X10/W10 -> 54.545455
A11: Qwen2.5 72B (2024) (AlibabaCloud) | B11: 72B | C11: 18T | D11: 250 | G11: ProtT5-XL-UniRef50 (initialized from ProtT5-XL-BFD) | H11: T5 denoising | I11: 3000000000 | J11: 1015296000000 | K11: 1.8275328e+22 | L11: =J11/I11 -> 338.432 | M11: Tokens computed from steps×batch×seq_len; FLOPs estimated (6×params×tokens) | N11: Source reports 991.5k steps, batch size 2,000, seq length 512 on TPU Pod V2-256. | U11: Caduceus | V11: DNA single-base | W11: 8000000 | X11: 35000000000 | Y11: 35000000000 | Z11: Not stated in table | AA11: 1.68 EFLOPs | AB11: 1.68e+18 | AC11: =X11/W11 -> 4375
A12: Avg Token / Param | D12: =AVERAGE(D3:D11) -> 81.804444 | G12: ProtBERT-BFD | H12: MLM | I12: 420000000 | J12: 393000000000 | K12: 9.24336e+20 | L12: =J12/I12 -> 935.71429 | M12: Tokens from BFD amino-acid count; FLOPs estimated (~5.6×params×tokens) | N12: Token count uses BFD total amino acids; training epochs/total seen tokens not always reported. | U12: Enformer | V12: DNA single-base | W12: 252000000 | X12: 64000000000 | Y12: 64000000000 | Z12: Not stated in table | AA12: 96.77 EFLOPs | AB12: 9.677e+19 | AC12: =X12/W12 -> 253.96825
G13: ESM-1b | H13: MLM | I13: 650000000 | J13: 86000000000 | K13: 3.1304e+20 | L13: =J13/I13 -> 132.30769 | M13: Tokens from dataset amino-acid count; FLOPs estimated (~5.6×params×tokens) | N13: Token count uses dataset total amino acids. | AC13: =AVERAGE(AC3:AC12) -> 2374.6573
A14: MoEs | G14: Avg Token / Param | L14: =AVERAGE(L3:L13) -> 308.49653
A15: Model (year) | B15: Params (total / active) | C15: Pretrain tokens | D15: Tokens / total param | E15: Tokens / active param | G15: Video
A16: DBRX (2024) (Databricks) | B16: 132B / 36B | C16: 12T | D16: 90.91 | E16: 333.33 | G16: Model | H16: Parameters | I16: Training compute (publicly disclosed) | J16: Training “tokens” / data (publicly disclosed) | U16: Seq-to-Structure
A17: DeepSeek-V2 (2024) (arXiv) | B17: 236B / 21B | C17: 8.1T | D17: 34.32 | E17: 385.71 | G17: Meta MovieGenVideo | H17: 30B | I17: Paper reports training at scale with up to 6,144 H100 GPUs (but does not give a single “total FLOPs” or “total GPU‑hours” number). | J17: Pretrained on ~100M videos + ~1B images and uses 73K video tokens context length (16s @ 16fps @ 768²). | U17: Model | V17: Parameters | W17: Training tokens (computed from reported crops + samples) | X17: Compute | Y17: What the papers/cards report that supports the token calc | Z17: Tokens/param
A18: DeepSeek-V3 (2024) (arXiv) | B18: 671B / 37B | C18: 14.8T | D18: 22.06 | E18: 400 | G18: Step‑Video‑T2V (StepFun) | H18: 30B | I18: Describes training in a datacenter with thousands of NVIDIA H800 GPUs and achieving 99% effective GPU training time over >1 month (but no total compute figure). | J18: Reports 2B video‑text pairs + 3.8B image‑text pairs for pretraining data construction, and a pretraining recipe with #iters and #seen samples (e.g., 3.8B images; ~671M video clips across stages shown). | U18: OpenFold | V18: 93000000 | W18: 3328000000 | Y18: 3 training phases run for 10M, 1.5M, 0.5M protein samples; training follows AlphaFold2 crop sizes (256 then 384). (PubMed Central) | Z18: =W18/V18 -> 35.784946
A19: Kimi K2 (2025) (Medium) | B19: 1T / 32B | C19: 15.5T | D19: 15.5 | E19: 484.38 | G19: Open‑Sora 2.0 | H19: 11B | I19: Training cost breakdown includes 4,160 GPU‑days total (≈ 99,840 GPU‑hours) for a full run under a stated cost assumption (“H200 at $2/GPU‑hour”), with stages like 224 GPUs × 85k iters, etc. | J19: Uses “tokens” explicitly: notes an 8s high‑res clip could be ~115K tokens/video under certain VAE+patch settings, and provides max‑token buckets (e.g., 8,448 max tokens at 256px; 76,032 max tokens at 768px). Also lists stage dataset sizes (e.g., 70M / 10M / 5M). | U19: OpenFold3 | V19: 368000000 | W19: 11174400000 | Y19: AlphaFold3 training stages: Ntoken = 384 / 640 / 768 / 768 with training samples ≈ 20M / 1.5M / 1.5M / 1.8M; OpenFold3 weights follow the AlphaFold3 procedure. (Springer Static Content) | Z19: =W19/V19 -> 30.365217
A20: Qwen3 up to 235B (2025) (arXiv) | B20: 235B / 22B | C20: 36T | D20: 153.19 | E20: 1636 | G20: Tencent HunyuanVideo | H20: >13B (reported as “over 13B parameters”) | I20: Not disclosed publicly (in the abstract snippet; full report may include more, but it’s not in the publicly visible abstract data). | J20: Not disclosed publicly as “total tokens”; not standardized in public materials. | U20: ESMFold (ESM2-based folding head) | V20: 3000000000 | W20: 86000000000 | X20: ~896 GPU-days (as reported via a comparative source) | Z20: =W20/V20 -> 28.666667
D21: =AVERAGE(D16:D20) -> 63.196 | E21: =AVERAGE(E16:E20) -> 647.884 | G21: Wan2.2 (Wan‑Video, MoE “A14B” line) | H21: 27B total / 14B active per step for the MoE A14B series; also mentions a 5B dense TI2V model. | I21: Training compute not disclosed in the repo README. | J21: Training tokens/data scale not disclosed in the repo README. | U21: HelixFold | V21: 93000000 | W21: 3136000000 | Y21: https://arxiv.org/pdf/2207.05477 | Z21: =W21/V21 -> 33.72043
Z22: =AVERAGE(Z18:Z21) -> 32.134315
A23: Optimal params | B23: Training FLOPs | C23: FLOPs (Gopher units) | D23: Optimal tokens | E23: Tokens / parameter
A24: 400M | B24: 1.92×10¹⁹ | C24: 1/29,968 | D24: 8.0B | E24: 20 | U24: OmegaFold | V24: Not reliably cited from an accessible primary snippet here | W24: ~3456 GPU-days (comparative source) | X24: Not reliably cited from an accessible primary snippet here | Y24: Comparative paper reports OmegaFold training consumption around 3456 GPU-days. (Nature)
A25: 1B | B25: 1.21×10²⁰ | C25: 1/4,761 | D25: 20.2B | E25: 20.2 | U25: AlphaFold2 (DeepMind) | V25: Often cited ~90M-class, but I don’t have a citable snippet in the accessible sources here | W25: 128 TPUs × >11 days (chip-time) | X25: 10M samples (not “tokens”) | Y25: NVIDIA’s OpenFold optimization post states AlphaFold2 training used 10M samples with 128 TPUs and took >11 days to converge. (NVIDIA Developer) (This is chip-time and sample count; “tokens” per sample aren’t specified there.)
A26: 10B | B26: 1.23×10²² | C26: 16803 | D26: 205.1B | E26: 20.51 | U26: OpenFold (retraining AlphaFold2-style model) | V26: Not reliably cited from an accessible primary snippet here | W26: 128 A100 GPUs × >8 days (chip-time) | X26: Not in cited snippet | Y26: Same NVIDIA post states OpenFold training on 128 A100 GPUs takes >8 days. (NVIDIA Developer)
A27: 67B | B27: 5.76×10²³ | C27: 1 | D27: 1.5T | E27: 22.39 | G27: Autonomous driving | H27: Parameters | I27: Tokens | J27: Tokens / parms | U27: Uni-Fold | V27: Not reliably cited from an accessible primary snippet here | W27: ~4.18 days end-to-end training time (chip-time not fully specified) | X27: Not in cited snippet | Y27: An arXiv PDF snippet states end-to-end AlphaFold2 training time reduced to 4.18 days on UniFold. (arXiv)
A28: 175B | B28: 3.85×10²⁴ | C28: 6.7 | D28: 3.7T | E28: 21.14 | G28: GAIA-1 | H28: 6500000000 | I28: 241920000000 | J28: =I28/H28 -> 37.218462 | K28: Reported: dataset ≈ 4,700 hours @ 25 Hz = ~420M unique images. \nReported: each image encoded as 18×32 = 576 discrete tokens. \nDerived image-token count: 420,000,000 × 576 = 241,920,000,000 ≈ 2.42×10¹¹ tokens (image tokens only). | U28: HelixFold (AlphaFold2-style training system) | V28: Not reliably cited from an accessible primary snippet here | W28: ~4.88 days end-to-end training time (chip-time not fully specified) | X28: Not in cited snippet | Y28: Same arXiv PDF snippet states 4.88 days on HelixFold. (arXiv)
A29: 280B | B29: 9.90×10²⁴ | C29: 17.2 | D29: 5.9T | E29: 21.07 | G29: GAIA-1 image tokenizer | H29: 0.3B (ar5iv) | I29: 18.432B = 200k steps × 160 batch × 576 tokens/image (ar5iv) | J29: 61.44 | U29: HelixFold-Single (single-sequence folding, LM + AF2 geometry) | V29: Not in cited snippet | W29: Not in cited snippet | X29: Training set described as ~340k proteins (80,852 experimental + ~264k distillation) | Y29: Full-text (PMC) snippet describes training data composition: ~340k proteins, including 80,852 with experimental structures and ~264k AlphaFold2-distillation structures. (PMC)
A30: 520B | B30: 3.43×10²⁵ | C30: 59.5 | D30: 11.0T | E30: 21.15 | G30: GAIA-1 world model | H30: 6.5B (ar5iv) | I30: 203.008B = 100k steps × 128 batch × 26 × (576 image + 32 text + 2 action) (ar5iv) | J30: 31.23 | U30: RoseTTAFold / RoseTTAFold2 / RF-based folding | V30: Not in the accessible sources I could cite here | W30: Not in the accessible sources I could cite here | X30: Not in the accessible sources I could cite here | Y30: These are extremely popular, but parameter/compute/token metadata is often not disclosed in a neat “params/compute/tokens” trio in public summaries; you usually must extract from the paper’s methods/supplement. (I can’t reliably cite the trio from the sources available to me above.)
A31: 1T | B31: 1.27×10²⁶ | C31: 221.3 | D31: 21.2T | E31: 21.2 | G31: GAIA-2 world model | H31: 8.4B (arXiv) | I31: 1,483.776B (1.484T) = 460k steps × 256 batch × 12,600 tokens/sample, where 12,600 = 6×5×14×30 (arXiv) | J31: 176.64
A32: 10T | B32: 1.30×10²⁸ | C32: 22515.9 | D32: 216.2T | E32: 21.62 | G32: GAIA-3 world model (estimate) | H32: 15B (Wayve) | I32: ~7.42T to ~14.84T (est.) using Wayve’s “~5× compute” and “~10× data vs GAIA-2” (no public step/batch/token formula) (Wayve) | J32: 742
J33: =AVERAGE(J28:J32) -> 209.70569
G34: Robotics
A35: Tokens / Parameters | G35: Model / variant | H35: Release year | I35: Total params | K35: Trainable params (during training) | L35: Training compute (reported) | M35: Training compute (est.) | N35: Training data / 'tokens' (reported) | O35: Token definition used | P35: Rigorous token metric | Q35: Tokens (lower) | R35: Tokens (upper) | S35: Token notes / what's missing | T35: Primary source(s) | U35: Avg Token Est | V35: Tokens/Param
B36: Median | C36: Avg | G36: OpenVLA (pretraining) | H36: 2024 | I36: 7B | K36: 7B | L36: 21,500 A100-hours (64×A100 for 14 days) | N36: 970k robot trajectories × 27 epochs = 26.19M trajectory-passes | O36: Trajectory-passes (trajectory-level; step-level tokens not disclosed)
A37: LLMs | B37: =MEDIAN(D3:D11,D16:D20) -> 35.68 | C37: =AVERAGE(D3:D11,D16:D20) -> 75.158571 | G37: OpenVLA fine-tune: Full FT | H37: 2024 | I37: 7B | K37: 7.188B (Table 1) | L37: Per task: 8×A100 for 5–15 hours (40–120 A100-hours) | N37: Per task: 10–150 demonstrations | O37: Demonstrations (episode-level)
A38: Non-LLMs | B38: =MEDIAN(L3:L13,J28:J32,V46:V61,P78:P80,P84:P89,Z18:Z21,AC3:AC12) -> 229.05759 | C38: =AVERAGE(L3:L13,J28:J32,V46:V61,P78:P80,P84:P89,Z18:Z21,AC3:AC12) -> 967.128 | G38: OpenVLA fine-tune: Last layer only | H38: 2024 | I38: 7B | K38: 465.1M (Table 1) | L38: Per task: 8×A100 for 5–15 hours (40–120 A100-hours) | N38: Per task: 10–150 demonstrations | O38: Demonstrations (episode-level)
A39: Image | B39: =MEDIAN(P78:P80,P84:P89) -> 974.31245 | C39: =P90 -> 1471.5668 | G39: OpenVLA fine-tune: Frozen vision | H39: 2024 | I39: 7B | K39: 6.760B (Table 1) | L39: Per task: 8×A100 for 5–15 hours (40–120 A100-hours) | N39: Per task: 10–150 demonstrations | O39: Demonstrations (episode-level)
A40: Bio -- Seq-to-Structure | B40: =MEDIAN(Z18:Z21) -> 32.042824 | C40: =Z22 -> 32.134315 | G40: OpenVLA fine-tune: Sandwich | H40: 2024 | I40: 7B | K40: 914.2M (Table 1) | L40: Per task: 8×A100 for 5–15 hours (40–120 A100-hours) | N40: Per task: 10–150 demonstrations | O40: Demonstrations (episode-level)
...

Sheet Table
B1: Clustered Non-Redundant Public Dataset Size (Tokens) | C1: Dataset Information Density (noise, sparsity, % relevant samples, quality) | D1: Median Model Token / Parameter Ratio | E1: Approximate Optimal Model Size | F1: Semi-Relevant Lower Quality Public Datasets (Tokens) | G1: Median Scaling Law Coefficient | H1: Intrinsic Dimension | I1: Tokenization | J1: Sources for Clustered Dataset | P1: Sources for larger dataset | S1: Sources for Optimal Model Size | W1: Sources for ID
A2: LLMs | B2: 3-15T | C2: High | D2: 35.68 | E2: 200-500B | F2: 40T | G2: =MEDIAN('Scaling Laws'!F3:H33) -> 0.32391702 | H2: 10-20 | I2: Solved | J2: https://arxiv.org/pdf/2306.01116 | K2: https://aclanthology.org/2024.acl-long.840.pdf | L2: https://papers.neurips.cc/paper_files/paper/2024/file/370df50ccfdf8bde18f8f9c2d9151bda-Paper-Datasets_and_Benchmarks_Track.pdf | M2: https://aclanthology.org/2025.acl-long.123.pdf | N2: https://openreview.net/pdf/969b1838ea8ccb4ffbeda9f958828f04656dba03.pdf | S2: https://huggingface.co/meta-llama/Llama-4-Scout-17B-16E-Instruct | T2: https://arxiv.org/abs/2203.15556 | W2: https://arxiv.org/abs/2306.04723
A3: Image | B3: 1-3T | C3: Medium | D3: 974.31245 | E3: 3B | F3: 12T | G3: =MEDIAN('Scaling Laws'!F23:H33) -> 0.29205422 | H3: 10-40 | I3: Somewhat | J3: https://arxiv.org/pdf/2303.12733 | K3: https://arxiv.org/abs/2303.09540 | L3: https://laion.ai/blog/laion-aesthetics/ | M3: https://ar5iv.labs.arxiv.org/html/2204.06125 | N3: https://ar5iv.labs.arxiv.org/html/2206.10789 | W3: https://openreview.net/pdf?id=XJk19XzGq2J | X3: https://arxiv.org/pdf/2008.04431
A4: Video | B4: 1-10T | C4: Medium | F4: 40T: including YouTube | G4: =MEDIAN('Scaling Laws'!F34:H43) -> 0.16330966 | I4: Somewhat | J4: https://arxiv.org/html/2410.13720v1 | K4: https://arxiv.org/html/2511.18870v1 | L4: https://arxiv.org/html/2502.10248v1
A5: Bio: Structural Models | B5: 30-300M in PDB + 10B MSAs from UniRef50 | C5: High | D5: 32.042824 | E5: 100M | F5: 500B: UniRef100 + Mgnify | G5: 39.61%* | H5: 5-20 | I5: Somewhat | J5: https://pmc.ncbi.nlm.nih.gov/articles/PMC11645889/ | P5: https://huggingface.co/datasets/builddotai/Egocentric-10K | W5: https://pmc.ncbi.nlm.nih.gov/articles/PMC6472826/ | X5: https://arxiv.org/pdf/2302.00294 | Y5: https://openreview.net/pdf/3fd0247fe61edc9010f6ee04bbfcb9220d8758b6.pdf | Z5: https://www.nature.com/articles/s41586-021-03819-2
A6: Bio: DNA and PLMs | B6: 10B in UniRef50 | C6: Medium | D6: 132.30769 | E6: 100M-1B | F6: 500B: UniRef100 + Mgnify | G6: =MEDIAN('Scaling Laws'!F56:H67) -> 0.09217947 | H6: 5-20 | I6: Somewhat | J6: https://www.biorxiv.org/content/10.1101/2025.06.11.658620v1.full.pdf | P6: https://www.uniprot.org/help/uniref | Q6: https://docs.mgnify.org/src/docs/mgnify-proteins.html | W6: https://arxiv.org/pdf/2302.00294 | X6: https://openreview.net/pdf/3fd0247fe61edc9010f6ee04bbfcb9220d8758b6.pdf
A7: Bio: Virtual Cell | B7: 10B | C7: Very Low | D7: 870.00864 | E7: 10M | F7: 30-500B: all cell atlases | G7: 3.17%* | I7: Not Solved | J7: https://pmc.ncbi.nlm.nih.gov/articles/PMC12003772/ | K7: https://pmc.ncbi.nlm.nih.gov/articles/PMC11370383/ | L7: https://www.biorxiv.org/content/10.1101/2023.11.28.568918v1 | M7: https://virtualcellmodels.cziscience.com/model/01966441-339f-77f7-aa06-f67636f865dc | N7: https://arcinstitute.org/news/foundation-model-stack | O7: https://academic.oup.com/nar/article/doi/10.1093/nar/gkaf805/8245241 | S7: https://chanzuckerberg.github.io/cellxgene-census/cellxgene_census_docsite_data_release_info.html
A8: Autonomous Vehicles | B8: 10-200B | C8: Low | D8: 61.44 | E8: 3B | F8: Video data | G8: =MEDIAN('Scaling Laws'!F54:H55) -> 0.17418662 | I8: Somewhat | J8: https://huggingface.co/datasets/nvidia/PhysicalAI-Autonomous-Vehicles | K8: https://openaccess.thecvf.com/content/CVPR2024/papers/Yang_Generalized_Predictive_Model_for_Autonomous_Driving_CVPR_2024_paper.pdf | L8: https://bair.berkeley.edu/blog/2018/05/30/bdd/ | M8: https://arxiv.org/abs/2510.26125 | P8: https://ar5iv.org/pdf/2309.17080 | Q8: https://www.notateslaapp.com/software-updates/version/2024.3.25/release-notes | R8: https://www.sec.gov/Archives/edgar/data/1867729/000117184325001490/exh_991.htm | S8: https://arxiv.org/pdf/2506.08228
A9: Robotics | B9: 100M-1B action tokens + 30B robot visual tokens | C9: Low | D9: 135.93241 | E9: 200M | F9: 250B: egocentric task video 3T: task demo videos 40T: YouTube | G9: =MEDIAN('Scaling Laws'!F47:H53) -> 0.30879974 | H9: 40+ | I9: Not Solved | J9: https://www.roboticsproceedings.org/rss20/p120.pdf | K9: https://rh20t.github.io/static/RH20T_paper_compressed.pdf | L9: https://www.tensorflow.org/datasets/catalog/robonet | M9: https://bridgedata-v2.github.io/ | N9: https://bridgedata-v2.github.io/ | O9: https://arxiv.org/html/2310.08864v4 | P9: https://openaccess.thecvf.com/content_ICCV_2019/papers/Miech_HowTo100M_Learning_a_Text-Video_Embedding_by_Watching_Hundred_Million_Narrated_ICCV_2019_paper.pdf | Q9: https://huggingface.co/datasets/builddotai/Egocentric-10K
